<?xml version="1.0"?>
<sdf version="1.8">
    <world name="Moving_robot">
        <physics name="1ms" type="ignored">
            <max_step_size>0.001</max_step_size>
            <real_time_factor>1.0</real_time_factor>
            <real_time_update_rate>1000</real_time_update_rate>
        </physics>
        <plugin
            filename="gz-sim-physics-system"
            name="gz::sim::systems::Physics">
        </plugin>
        <plugin
            filename="gz-sim-user-commands-system"
            name="gz::sim::systems::UserCommands">
        </plugin>
        <plugin
            filename="gz-sim-scene-broadcaster-system"
            name="gz::sim::systems::SceneBroadcaster">
        </plugin>

        <plugin
            filename="gz-sim-sensors-system"
            name="gz::sim::systems::Sensors">
        </plugin>
        <gui fullscreen='false'>
            <plugin name='3D View' filename='GzScene3D'>
                <gz-gui>
                    <title>3D View</title>
                    <property type='bool' key='showTitleBar'>0</property>
                    <property type='string' key='state'>docked</property>
                </gz-gui>
                <engine>ogre2</engine>
                <scene>scene</scene>

                <!-- day -->
                <!-- <ambient_light>0.5984631152222222 0.5984631152222222
                0.5984631152222222</ambient_light> -->

                <background_color>0.8984631152222222 0.8984631152222222 0.8984631152222222</background_color>
                <camera_pose>-6 0 6 0 0.5 0</camera_pose>
            </plugin>
            <plugin name='World control' filename='WorldControl'>
                <gz-gui>
                    <title>World control</title>
                    <property type='bool' key='showTitleBar'>0</property>
                    <property type='bool' key='resizable'>0</property>
                    <property type='double' key='height'>72</property>
                    <property type='double' key='width'>121</property>
                    <property type='double' key='z'>1</property>
                    <property type='string' key='state'>floating</property>
                    <anchors target='3D View'>
                        <line own='left' target='left' />
                        <line own='bottom' target='bottom' />
                    </anchors>
                </gz-gui>
                <play_pause>1</play_pause>
                <step>1</step>
                <start_paused>1</start_paused>
            </plugin>
            <plugin name='World stats' filename='WorldStats'>
                <gz-gui>
                    <title>World stats</title>
                    <property type='bool' key='showTitleBar'>0</property>
                    <property type='bool' key='resizable'>0</property>
                    <property type='double' key='height'>110</property>
                    <property type='double' key='width'>290</property>
                    <property type='double' key='z'>1</property>
                    <property type='string' key='state'>floating</property>
                    <anchors target='3D View'>
                        <line own='right' target='right' />
                        <line own='bottom' target='bottom' />
                    </anchors>
                </gz-gui>
                <sim_time>1</sim_time>
                <real_time>1</real_time>
                <real_time_factor>0.2</real_time_factor>
                <iterations>1</iterations>
            </plugin>
            <plugin name='Entity tree' filename='EntityTree' />
            <plugin filename="ImageDisplay" name="Image Display">
                <ignition-gui>
                    <property key="state" type="string">docked</property>
                </ignition-gui>
            </plugin>
            <plugin filename="Teleop" name="Teleop">
                <topic>/model/vehicle_blue/cmd_vel</topic>
                <gz-gui>
                    <title>Teleop</title>
                    <property key="state" type="string">docked</property>
                </gz-gui>
            </plugin>

        </gui>
        <scene>
            <grid>false</grid>
            <ambient>0.6 0.6 0.6 1.0</ambient>
            <shadows>1</shadows>
            <grid>false</grid>
            <sky />
        </scene>
        <!-- <include>
            <uri>model://sun</uri>
            <pose>0.0 0.0 40.0 0 0 0</pose>
            <cast_shadows>true</cast_shadows>
            <attenuation>
            <constant>0.5</constant>
            <linear>0.01</linear>
            <quadratic>0.0</quadratic>
            <range>100</range>
            </attenuation>
        </include> -->
        <light name="Main" type="point">
            <pose>0 0 40 0 0 0</pose>
            <diffuse>0.225 0.225 0.225 1</diffuse>
            <specular>.1 .1 .1 1</specular>
            <attenuation>
                <constant>0.4</constant>
                <linear>0.01</linear>
                <quadratic>0.00</quadratic>
                <range>50</range>
            </attenuation>
            <direction>0 0 -1</direction>
            <cast_shadows>true</cast_shadows>
        </light>
        <light name="Light2" type="point">
            <pose>20 20 40 0 0 0</pose>
            <diffuse>0.225 0.225 0.225 1</diffuse>
            <specular>.1 .1 .1 1</specular>
            <attenuation>
                <constant>0.4</constant>
                <linear>0.01</linear>
                <quadratic>0.00</quadratic>
                <range>50</range>
            </attenuation>
            <direction>0 0 -1</direction>
            <cast_shadows>true</cast_shadows>
        </light>
        <light name="Light3" type="point">
            <pose>-20 -20 40 0 0 0</pose>
            <diffuse>0.225 0.225 0.225 1</diffuse>
            <specular>.1 .1 .1 1</specular>
            <attenuation>
                <constant>0.4</constant>
                <linear>0.01</linear>
                <quadratic>0.00</quadratic>
                <range>50</range>
            </attenuation>
            <direction>0 0 -1</direction>
            <cast_shadows>true</cast_shadows>
        </light>
        <include>
            <uri>model://Trapezoid_model.sdf</uri>
            <pose>-25 -25 0 0 0 0</pose>
            <name>racetrack</name>
        </include>

        <light type="directional" name="sun">
            <cast_shadows>true</cast_shadows>
            <pose>0 0 10 0 0 0</pose>
            <diffuse>0.8 0.8 0.8 1</diffuse>
            <specular>0.2 0.2 0.2 1</specular>
            <attenuation>
                <range>1000</range>
                <constant>0.9</constant>
                <linear>0.01</linear>
                <quadratic>0.001</quadratic>
            </attenuation>
            <direction>-0.5 0.1 -0.9</direction>
        </light>

        <model name="ground_plane">
            <static>true</static>
            <link name="link">
                <collision name="collision">
                    <geometry>
                        <plane>
                            <normal>0 0 1</normal>
                        </plane>
                    </geometry>
                    <surface>
                        <friction>
                            <ode>
                                <mu>50</mu>
                            </ode>
                        </friction>
                        <bounce />
                        <contact />
                    </surface>
                </collision>
                <visual name="visual">
                    <geometry>
                        <plane>
                            <normal>0 0 1</normal>
                            <size>100 100</size>
                        </plane>
                    </geometry>
                    <material>
                        <ambient>0.8 0.8 0.8 1</ambient>
                        <diffuse>0.8 0.8 0.8 1</diffuse>
                        <specular>0.8 0.8 0.8 1</specular>
                    </material>
                </visual>
            </link>
        </model>

        <model name='vehicle_blue' xmlns:gz='http://gazebosim.org/schema'>
            <pose>-22.05 5.24 0.33 0 0 -1.55</pose>
            <link name='chassis'>
                <sensor name="camera" type="camera">
                    <pose relative_to="base_link"> 0.2 0 0.01 0 0 0 </pose>
                    <camera>
                        <horizontal_fov>1.047</horizontal_fov>
                        <image>
                            <width>320</width>
                            <height>240</height>
                        </image>
                        <clip>
                            <near>0.1</near>
                            <far>100</far>
                        </clip>
                    </camera>
                    <always_on>1</always_on>
                    <update_rate>120</update_rate>
                    <visualize>true</visualize>
                    <topic>camera</topic>
                </sensor>
                <pose>-0.15142700000000001 0 0.17499999999999999 0 0 0</pose>
                <inertial>
                    <mass>1.14395</mass>
                    <inertia>
                        <ixx>0.126164</ixx>
                        <ixy>0</ixy>
                        <ixz>0</ixz>
                        <iyy>0.41651899999999997</iyy>
                        <iyz>0</iyz>
                        <izz>0.481014</izz>
                    </inertia>
                    <pose>0 0 0 0 0 0</pose>
                </inertial>
                <visual name='visual'>
                    <geometry>
                        <box>
                            <size>2.0114200000000002 1 0.56872599999999995</size>
                        </box>
                    </geometry>
                    <material>
                        <ambient>0.5 0.5 1 1</ambient>
                        <diffuse>0.5 0.5 1 1</diffuse>
                        <specular>0 0 1 1</specular>
                    </material>
                </visual>
                <collision name='collision'>
                    <geometry>
                        <box>
                            <size>2.0114200000000002 1 0.56872599999999995</size>
                        </box>
                    </geometry>
                    <surface>
                        <friction>
                            <ode />
                        </friction>
                        <bounce />
                        <contact />
                    </surface>
                </collision>
                <enable_wind>false</enable_wind>
            </link>
            <link name='front_left_wheel'>
                <pose>0.55428299999999997 0.62502900000000006 -0.025000000000000022
                    -1.5706999999999995 0 0</pose>
                <inertial>
                    <mass>2</mass>
                    <inertia>
                        <ixx>0.14583299999999999</ixx>
                        <ixy>0</ixy>
                        <ixz>0</ixz>
                        <iyy>0.14583299999999999</iyy>
                        <iyz>0</iyz>
                        <izz>0.125</izz>
                    </inertia>
                    <pose>0 0 0 0 0 0</pose>
                </inertial>
                <visual name='visual'>
                    <pose>0 0 0 1.5707 0 0</pose>
                    <geometry>
                        <mesh>
                            <uri>https://fuel.gazebosim.org/1.0/OpenRobotics/models/Mecanum
                                lift/tip/files/meshes/mecanum_wheel_left.STL</uri>
                            <scale>0.0060000000000000001 0.0060000000000000001 0.0060000000000000001</scale>
                        </mesh>
                    </geometry>
                    <material>
                        <ambient>0.200000003 0.200000003 0.200000003 1</ambient>
                        <diffuse>0.200000003 0.200000003 0.200000003 1</diffuse>
                        <specular>0.200000003 0.200000003 0.200000003 1</specular>
                    </material>
                </visual>
                <collision name='collision'>
                    <geometry>
                        <sphere>
                            <radius>0.29999999999999999</radius>
                        </sphere>
                    </geometry>
                    <surface>
                        <friction>
                            <ode>
                                <mu>1</mu>
                                <mu2>0</mu2>
                                <fdir1 gz:expressed_in='chassis'>1 -1 0</fdir1>
                            </ode>
                        </friction>
                        <bounce />
                        <contact />
                    </surface>
                </collision>
                <enable_wind>false</enable_wind>
            </link>
            <link name='rear_left_wheel'>
                <pose>-0.95713800000000004 0.62502900000000006 -0.025000000000000022
                    -1.5706999999999995 0 0</pose>
                <inertial>
                    <mass>2</mass>
                    <inertia>
                        <ixx>0.14583299999999999</ixx>
                        <ixy>0</ixy>
                        <ixz>0</ixz>
                        <iyy>0.14583299999999999</iyy>
                        <iyz>0</iyz>
                        <izz>0.125</izz>
                    </inertia>
                    <pose>0 0 0 0 0 0</pose>
                </inertial>
                <visual name='visual'>
                    <pose>0 0 0 1.5707 0 0</pose>
                    <geometry>
                        <mesh>
                            <uri>https://fuel.gazebosim.org/1.0/OpenRobotics/models/Mecanum
                                lift/tip/files/meshes/mecanum_wheel_right.STL</uri>
                            <scale>0.0060000000000000001 0.0060000000000000001 0.0060000000000000001</scale>
                        </mesh>
                    </geometry>
                    <material>
                        <ambient>0.200000003 0.200000003 0.200000003 1</ambient>
                        <diffuse>0.200000003 0.200000003 0.200000003 1</diffuse>
                        <specular>0.200000003 0.200000003 0.200000003 1</specular>
                    </material>
                </visual>
                <collision name='collision'>
                    <geometry>
                        <sphere>
                            <radius>0.29999999999999999</radius>
                        </sphere>
                    </geometry>
                    <surface>
                        <friction>
                            <ode>
                                <mu>1</mu>
                                <mu2>0</mu2>
                                <fdir1 gz:expressed_in='chassis'>1 1 0</fdir1>
                            </ode>
                        </friction>
                        <bounce />
                        <contact />
                    </surface>
                </collision>
                <enable_wind>false</enable_wind>
            </link>
            <link name='front_right_wheel'>
                <pose>0.55428200000000005 -0.62502900000000006 -0.025000000000000022
                    -1.5706999999999995 0 0</pose>
                <inertial>
                    <mass>2</mass>
                    <inertia>
                        <ixx>0.14583299999999999</ixx>
                        <ixy>0</ixy>
                        <ixz>0</ixz>
                        <iyy>0.14583299999999999</iyy>
                        <iyz>0</iyz>
                        <izz>0.125</izz>
                    </inertia>
                    <pose>0 0 0 0 0 0</pose>
                </inertial>
                <visual name='visual'>
                    <pose>0 0 0 1.5707 0 0</pose>
                    <geometry>
                        <mesh>
                            <uri>https://fuel.gazebosim.org/1.0/OpenRobotics/models/Mecanum
                                lift/tip/files/meshes/mecanum_wheel_right.STL</uri>
                            <scale>0.0060000000000000001 0.0060000000000000001 0.0060000000000000001</scale>
                        </mesh>
                    </geometry>
                    <material>
                        <ambient>0.200000003 0.200000003 0.200000003 1</ambient>
                        <diffuse>0.200000003 0.200000003 0.200000003 1</diffuse>
                        <specular>0.200000003 0.200000003 0.200000003 1</specular>
                    </material>
                </visual>
                <collision name='collision'>
                    <geometry>
                        <sphere>
                            <radius>0.29999999999999999</radius>
                        </sphere>
                    </geometry>
                    <surface>
                        <friction>
                            <ode>
                                <mu>1</mu>
                                <mu2>0</mu2>
                                <fdir1 gz:expressed_in='chassis'>1 1 0</fdir1>
                            </ode>
                        </friction>
                        <bounce />
                        <contact />
                    </surface>
                </collision>
                <enable_wind>false</enable_wind>
            </link>
            <link name='rear_right_wheel'>
                <pose>-0.95713800000000004 -0.62502900000000006 -0.025000000000000022
                    -1.5706999999999995 0 0</pose>
                <inertial>
                    <mass>2</mass>
                    <inertia>
                        <ixx>0.14583299999999999</ixx>
                        <ixy>0</ixy>
                        <ixz>0</ixz>
                        <iyy>0.14583299999999999</iyy>
                        <iyz>0</iyz>
                        <izz>0.125</izz>
                    </inertia>
                    <pose>0 0 0 0 0 0</pose>
                </inertial>
                <visual name='visual'>
                    <pose>0 0 0 1.5707 0 0</pose>
                    <geometry>
                        <mesh>
                            <uri>https://fuel.gazebosim.org/1.0/OpenRobotics/models/Mecanum
                                lift/tip/files/meshes/mecanum_wheel_left.STL</uri>
                            <scale>0.0060000000000000001 0.0060000000000000001 0.0060000000000000001</scale>
                        </mesh>
                    </geometry>
                    <material>
                        <ambient>0.200000003 0.200000003 0.200000003 1</ambient>
                        <diffuse>0.200000003 0.200000003 0.200000003 1</diffuse>
                        <specular>0.200000003 0.200000003 0.200000003 1</specular>
                    </material>
                </visual>
                <collision name='collision'>
                    <geometry>
                        <sphere>
                            <radius>0.29999999999999999</radius>
                        </sphere>
                    </geometry>
                    <surface>
                        <friction>
                            <ode>
                                <mu>1</mu>
                                <mu2>0</mu2>
                                <fdir1 gz:expressed_in='chassis'>1 -1 0</fdir1>
                            </ode>
                        </friction>
                        <bounce />
                        <contact />
                    </surface>
                </collision>
                <enable_wind>false</enable_wind>
            </link>
            <joint name='front_left_wheel_joint' type='revolute'>
                <parent>chassis</parent>
                <child>front_left_wheel</child>
                <axis>
                    <xyz>0 0 1</xyz>
                    <limit>
                        <lower>-1.7976900000000001e+308</lower>
                        <upper>1.7976900000000001e+308</upper>
                        <effort>inf</effort>
                        <velocity>inf</velocity>
                        <stiffness>100000000</stiffness>
                        <dissipation>1</dissipation>
                    </limit>
                    <dynamics>
                        <spring_reference>0</spring_reference>
                        <spring_stiffness>0</spring_stiffness>
                        <damping>0</damping>
                        <friction>0</friction>
                    </dynamics>
                </axis>
                <pose>0 0 1.1102230246251565e-16 0 0 0</pose>
            </joint>
            <joint name='front_right_wheel_joint' type='revolute'>
                <parent>chassis</parent>
                <child>front_right_wheel</child>
                <axis>
                    <xyz>0 0 1</xyz>
                    <limit>
                        <lower>-1.7976900000000001e+308</lower>
                        <upper>1.7976900000000001e+308</upper>
                        <effort>inf</effort>
                        <velocity>inf</velocity>
                        <stiffness>100000000</stiffness>
                        <dissipation>1</dissipation>
                    </limit>
                    <dynamics>
                        <spring_reference>0</spring_reference>
                        <spring_stiffness>0</spring_stiffness>
                        <damping>0</damping>
                        <friction>0</friction>
                    </dynamics>
                </axis>
                <pose>-1.1102230246251565e-16 0 0 0 0 0</pose>
            </joint>
            <joint name='rear_left_wheel_joint' type='revolute'>
                <parent>chassis</parent>
                <child>rear_left_wheel</child>
                <axis>
                    <xyz>0 0 1</xyz>
                    <limit>
                        <lower>-1.7976900000000001e+308</lower>
                        <upper>1.7976900000000001e+308</upper>
                        <effort>inf</effort>
                        <velocity>inf</velocity>
                        <stiffness>100000000</stiffness>
                        <dissipation>1</dissipation>
                    </limit>
                    <dynamics>
                        <spring_reference>0</spring_reference>
                        <spring_stiffness>0</spring_stiffness>
                        <damping>0</damping>
                        <friction>0</friction>
                    </dynamics>
                </axis>
                <pose>0 0 1.1102230246251565e-16 0 0 0</pose>
            </joint>
            <joint name='rear_right_wheel_joint' type='revolute'>
                <parent>chassis</parent>
                <child>rear_right_wheel</child>
                <axis>
                    <xyz>0 0 1</xyz>
                    <limit>
                        <lower>-1.7976900000000001e+308</lower>
                        <upper>1.7976900000000001e+308</upper>
                        <effort>inf</effort>
                        <velocity>inf</velocity>
                        <stiffness>100000000</stiffness>
                        <dissipation>1</dissipation>
                    </limit>
                    <dynamics>
                        <spring_reference>0</spring_reference>
                        <spring_stiffness>0</spring_stiffness>
                        <damping>0</damping>
                        <friction>0</friction>
                    </dynamics>
                </axis>
                <pose>0 0 0 0 0 0</pose>
            </joint>
            <plugin name='gz::sim::systems::MecanumDrive' filename='gz-sim-mecanum-drive-system'>
                <front_left_joint>front_left_wheel_joint</front_left_joint>
                <front_right_joint>front_right_wheel_joint</front_right_joint>
                <back_left_joint>rear_left_wheel_joint</back_left_joint>
                <back_right_joint>rear_right_wheel_joint</back_right_joint>
                <wheel_separation>1.25</wheel_separation>
                <wheelbase>1.511</wheelbase>
                <wheel_radius>0.3</wheel_radius>
                <min_acceleration>-5</min_acceleration>
                <max_acceleration>5</max_acceleration>
            </plugin>
            <static>false</static>
            <self_collide>false</self_collide>
        </model>
    </world>
</sdf>