<sdf version='1.10'>
  <world name='mecanum_drive'>
    <physics name='1ms' type='ignored'>
      <max_step_size>0.001</max_step_size>
      <real_time_factor>1</real_time_factor>
      <real_time_update_rate>1000</real_time_update_rate>
    </physics>
    <plugin name='gz::sim::systems::Physics' filename='gz-sim-physics-system'/>
    <plugin name='gz::sim::systems::UserCommands' filename='gz-sim-user-commands-system'/>
    <plugin name='gz::sim::systems::SceneBroadcaster' filename='gz-sim-scene-broadcaster-system'/>
    <gravity>0 0 -9.8000000000000007</gravity>
    <magnetic_field>5.5644999999999998e-06 2.2875799999999999e-05 -4.2388400000000002e-05</magnetic_field>
    <atmosphere type='adiabatic'/>
    <scene>
      <ambient>0.400000006 0.400000006 0.400000006 1</ambient>
      <background>0.699999988 0.699999988 0.699999988 1</background>
      <shadows>true</shadows>
    </scene>
    <model name='ground_plane'>
      <static>true</static>
      <link name='link'>
        <collision name='collision'>
          <geometry>
            <plane>
              <normal>0 0 1</normal>
              <size>100 100</size>
            </plane>
          </geometry>
          <surface>
            <friction>
              <ode>
                <mu>50</mu>
              </ode>
            </friction>
            <bounce/>
            <contact/>
          </surface>
        </collision>
        <visual name='visual'>
          <geometry>
            <plane>
              <normal>0 0 1</normal>
              <size>100 100</size>
            </plane>
          </geometry>
          <material>
            <ambient>0.800000012 0.800000012 0.800000012 1</ambient>
            <diffuse>0.800000012 0.800000012 0.800000012 1</diffuse>
            <specular>0.800000012 0.800000012 0.800000012 1</specular>
          </material>
        </visual>
        <pose>0 0 0 0 0 0</pose>
        <inertial>
          <pose>0 0 0 0 0 0</pose>
          <mass>1</mass>
          <inertia>
            <ixx>1</ixx>
            <ixy>0</ixy>
            <ixz>0</ixz>
            <iyy>1</iyy>
            <iyz>0</iyz>
            <izz>1</izz>
          </inertia>
        </inertial>
        <enable_wind>false</enable_wind>
      </link>
      <pose>0 0 0 0 0 0</pose>
      <self_collide>false</self_collide>
    </model>
    <model name='vehicle_blue' xmlns:gz='http://gazebosim.org/schema'>
      <pose>0 2 0.32500000000000001 0 0 0</pose>
      <link name='chassis'>
        <pose>-0.15142700000000001 0 0.17499999999999999 0 0 0</pose>
        <inertial>
          <mass>1.14395</mass>
          <inertia>
            <ixx>0.126164</ixx>
            <ixy>0</ixy>
            <ixz>0</ixz>
            <iyy>0.41651899999999997</iyy>
            <iyz>0</iyz>
            <izz>0.481014</izz>
          </inertia>
          <pose>0 0 0 0 0 0</pose>
        </inertial>
        <visual name='visual'>
          <geometry>
            <box>
              <size>2.0114200000000002 1 0.56872599999999995</size>
            </box>
          </geometry>
          <material>
            <ambient>0.5 0.5 1 1</ambient>
            <diffuse>0.5 0.5 1 1</diffuse>
            <specular>0 0 1 1</specular>
          </material>
        </visual>
        <collision name='collision'>
          <geometry>
            <box>
              <size>2.0114200000000002 1 0.56872599999999995</size>
            </box>
          </geometry>
          <surface>
            <friction>
              <ode/>
            </friction>
            <bounce/>
            <contact/>
          </surface>
        </collision>
        <enable_wind>false</enable_wind>
      </link>
      <link name='front_left_wheel'>
        <pose>0.55428299999999997 0.62502900000000006 -0.025000000000000022 -1.5706999999999995 0 0</pose>
        <inertial>
          <mass>2</mass>
          <inertia>
            <ixx>0.14583299999999999</ixx>
            <ixy>0</ixy>
            <ixz>0</ixz>
            <iyy>0.14583299999999999</iyy>
            <iyz>0</iyz>
            <izz>0.125</izz>
          </inertia>
          <pose>0 0 0 0 0 0</pose>
        </inertial>
        <visual name='visual'>
          <pose>0 0 0 1.5707 0 0</pose>
          <geometry>
            <mesh>
              <uri>https://fuel.gazebosim.org/1.0/OpenRobotics/models/Mecanum lift/tip/files/meshes/mecanum_wheel_left.STL</uri>
              <scale>0.0060000000000000001 0.0060000000000000001 0.0060000000000000001</scale>
            </mesh>
          </geometry>
          <material>
            <ambient>0.200000003 0.200000003 0.200000003 1</ambient>
            <diffuse>0.200000003 0.200000003 0.200000003 1</diffuse>
            <specular>0.200000003 0.200000003 0.200000003 1</specular>
          </material>
        </visual>
        <collision name='collision'>
          <geometry>
            <sphere>
              <radius>0.29999999999999999</radius>
            </sphere>
          </geometry>
          <surface>
            <friction>
              <ode>
                <mu>1</mu>
                <mu2>0</mu2>
                <fdir1 gz:expressed_in='chassis'>1 -1 0</fdir1>
              </ode>
            </friction>
            <bounce/>
            <contact/>
          </surface>
        </collision>
        <enable_wind>false</enable_wind>
      </link>
      <link name='rear_left_wheel'>
        <pose>-0.95713800000000004 0.62502900000000006 -0.025000000000000022 -1.5706999999999995 0 0</pose>
        <inertial>
          <mass>2</mass>
          <inertia>
            <ixx>0.14583299999999999</ixx>
            <ixy>0</ixy>
            <ixz>0</ixz>
            <iyy>0.14583299999999999</iyy>
            <iyz>0</iyz>
            <izz>0.125</izz>
          </inertia>
          <pose>0 0 0 0 0 0</pose>
        </inertial>
        <visual name='visual'>
          <pose>0 0 0 1.5707 0 0</pose>
          <geometry>
            <mesh>
              <uri>https://fuel.gazebosim.org/1.0/OpenRobotics/models/Mecanum lift/tip/files/meshes/mecanum_wheel_right.STL</uri>
              <scale>0.0060000000000000001 0.0060000000000000001 0.0060000000000000001</scale>
            </mesh>
          </geometry>
          <material>
            <ambient>0.200000003 0.200000003 0.200000003 1</ambient>
            <diffuse>0.200000003 0.200000003 0.200000003 1</diffuse>
            <specular>0.200000003 0.200000003 0.200000003 1</specular>
          </material>
        </visual>
        <collision name='collision'>
          <geometry>
            <sphere>
              <radius>0.29999999999999999</radius>
            </sphere>
          </geometry>
          <surface>
            <friction>
              <ode>
                <mu>1</mu>
                <mu2>0</mu2>
                <fdir1 gz:expressed_in='chassis'>1 1 0</fdir1>
              </ode>
            </friction>
            <bounce/>
            <contact/>
          </surface>
        </collision>
        <enable_wind>false</enable_wind>
      </link>
      <link name='front_right_wheel'>
        <pose>0.55428200000000005 -0.62502900000000006 -0.025000000000000022 -1.5706999999999995 0 0</pose>
        <inertial>
          <mass>2</mass>
          <inertia>
            <ixx>0.14583299999999999</ixx>
            <ixy>0</ixy>
            <ixz>0</ixz>
            <iyy>0.14583299999999999</iyy>
            <iyz>0</iyz>
            <izz>0.125</izz>
          </inertia>
          <pose>0 0 0 0 0 0</pose>
        </inertial>
        <visual name='visual'>
          <pose>0 0 0 1.5707 0 0</pose>
          <geometry>
            <mesh>
              <uri>https://fuel.gazebosim.org/1.0/OpenRobotics/models/Mecanum lift/tip/files/meshes/mecanum_wheel_right.STL</uri>
              <scale>0.0060000000000000001 0.0060000000000000001 0.0060000000000000001</scale>
            </mesh>
          </geometry>
          <material>
            <ambient>0.200000003 0.200000003 0.200000003 1</ambient>
            <diffuse>0.200000003 0.200000003 0.200000003 1</diffuse>
            <specular>0.200000003 0.200000003 0.200000003 1</specular>
          </material>
        </visual>
        <collision name='collision'>
          <geometry>
            <sphere>
              <radius>0.29999999999999999</radius>
            </sphere>
          </geometry>
          <surface>
            <friction>
              <ode>
                <mu>1</mu>
                <mu2>0</mu2>
                <fdir1 gz:expressed_in='chassis'>1 1 0</fdir1>
              </ode>
            </friction>
            <bounce/>
            <contact/>
          </surface>
        </collision>
        <enable_wind>false</enable_wind>
      </link>
      <link name='rear_right_wheel'>
        <pose>-0.95713800000000004 -0.62502900000000006 -0.025000000000000022 -1.5706999999999995 0 0</pose>
        <inertial>
          <mass>2</mass>
          <inertia>
            <ixx>0.14583299999999999</ixx>
            <ixy>0</ixy>
            <ixz>0</ixz>
            <iyy>0.14583299999999999</iyy>
            <iyz>0</iyz>
            <izz>0.125</izz>
          </inertia>
          <pose>0 0 0 0 0 0</pose>
        </inertial>
        <visual name='visual'>
          <pose>0 0 0 1.5707 0 0</pose>
          <geometry>
            <mesh>
              <uri>https://fuel.gazebosim.org/1.0/OpenRobotics/models/Mecanum lift/tip/files/meshes/mecanum_wheel_left.STL</uri>
              <scale>0.0060000000000000001 0.0060000000000000001 0.0060000000000000001</scale>
            </mesh>
          </geometry>
          <material>
            <ambient>0.200000003 0.200000003 0.200000003 1</ambient>
            <diffuse>0.200000003 0.200000003 0.200000003 1</diffuse>
            <specular>0.200000003 0.200000003 0.200000003 1</specular>
          </material>
        </visual>
        <collision name='collision'>
          <geometry>
            <sphere>
              <radius>0.29999999999999999</radius>
            </sphere>
          </geometry>
          <surface>
            <friction>
              <ode>
                <mu>1</mu>
                <mu2>0</mu2>
                <fdir1 gz:expressed_in='chassis'>1 -1 0</fdir1>
              </ode>
            </friction>
            <bounce/>
            <contact/>
          </surface>
        </collision>
        <enable_wind>false</enable_wind>
      </link>
      <joint name='front_left_wheel_joint' type='revolute'>
        <parent>chassis</parent>
        <child>front_left_wheel</child>
        <axis>
          <xyz>0 0 1</xyz>
          <limit>
            <lower>-1.7976900000000001e+308</lower>
            <upper>1.7976900000000001e+308</upper>
            <effort>inf</effort>
            <velocity>inf</velocity>
            <stiffness>100000000</stiffness>
            <dissipation>1</dissipation>
          </limit>
          <dynamics>
            <spring_reference>0</spring_reference>
            <spring_stiffness>0</spring_stiffness>
            <damping>0</damping>
            <friction>0</friction>
          </dynamics>
        </axis>
        <pose>0 0 1.1102230246251565e-16 0 0 0</pose>
      </joint>
      <joint name='front_right_wheel_joint' type='revolute'>
        <parent>chassis</parent>
        <child>front_right_wheel</child>
        <axis>
          <xyz>0 0 1</xyz>
          <limit>
            <lower>-1.7976900000000001e+308</lower>
            <upper>1.7976900000000001e+308</upper>
            <effort>inf</effort>
            <velocity>inf</velocity>
            <stiffness>100000000</stiffness>
            <dissipation>1</dissipation>
          </limit>
          <dynamics>
            <spring_reference>0</spring_reference>
            <spring_stiffness>0</spring_stiffness>
            <damping>0</damping>
            <friction>0</friction>
          </dynamics>
        </axis>
        <pose>-1.1102230246251565e-16 0 0 0 0 0</pose>
      </joint>
      <joint name='rear_left_wheel_joint' type='revolute'>
        <parent>chassis</parent>
        <child>rear_left_wheel</child>
        <axis>
          <xyz>0 0 1</xyz>
          <limit>
            <lower>-1.7976900000000001e+308</lower>
            <upper>1.7976900000000001e+308</upper>
            <effort>inf</effort>
            <velocity>inf</velocity>
            <stiffness>100000000</stiffness>
            <dissipation>1</dissipation>
          </limit>
          <dynamics>
            <spring_reference>0</spring_reference>
            <spring_stiffness>0</spring_stiffness>
            <damping>0</damping>
            <friction>0</friction>
          </dynamics>
        </axis>
        <pose>0 0 1.1102230246251565e-16 0 0 0</pose>
      </joint>
      <joint name='rear_right_wheel_joint' type='revolute'>
        <parent>chassis</parent>
        <child>rear_right_wheel</child>
        <axis>
          <xyz>0 0 1</xyz>
          <limit>
            <lower>-1.7976900000000001e+308</lower>
            <upper>1.7976900000000001e+308</upper>
            <effort>inf</effort>
            <velocity>inf</velocity>
            <stiffness>100000000</stiffness>
            <dissipation>1</dissipation>
          </limit>
          <dynamics>
            <spring_reference>0</spring_reference>
            <spring_stiffness>0</spring_stiffness>
            <damping>0</damping>
            <friction>0</friction>
          </dynamics>
        </axis>
        <pose>0 0 0 0 0 0</pose>
      </joint>
      <plugin name='gz::sim::systems::MecanumDrive' filename='gz-sim-mecanum-drive-system'>
        <front_left_joint>front_left_wheel_joint</front_left_joint>
        <front_right_joint>front_right_wheel_joint</front_right_joint>
        <back_left_joint>rear_left_wheel_joint</back_left_joint>
        <back_right_joint>rear_right_wheel_joint</back_right_joint>
        <wheel_separation>1.25</wheel_separation>
        <wheelbase>1.511</wheelbase>
        <wheel_radius>0.3</wheel_radius>
        <min_acceleration>-5</min_acceleration>
        <max_acceleration>5</max_acceleration>
      </plugin>
      <static>false</static>
      <self_collide>false</self_collide>
    </model>
    <light name='sun' type='directional'>
      <pose>0 0 10 0 0 0</pose>
      <cast_shadows>true</cast_shadows>
      <intensity>1</intensity>
      <direction>-0.5 0.10000000000000001 -0.90000000000000002</direction>
      <diffuse>1 1 1 1</diffuse>
      <specular>0.5 0.5 0.5 1</specular>
      <attenuation>
        <range>1000</range>
        <linear>0.01</linear>
        <constant>0.90000000000000002</constant>
        <quadratic>0.001</quadratic>
      </attenuation>
      <spot>
        <inner_angle>0</inner_angle>
        <outer_angle>0</outer_angle>
        <falloff>0</falloff>
      </spot>
    </light>
  </world>
</sdf>
